[INFO   ] Logger: Record log in /storage/emulated/0/matex/.kivy/logs/kivy_22-10-10_82.txt
[INFO   ] Kivy: v2.0.0
[INFO   ] Kivy: Installed at "/data/user/0/ru.iiec.pydroid3/files/arm-linux-androideabi/lib/python3.9/site-packages/kivy/__init__.py"
[INFO   ] Python: v3.9.7 (default, Oct  9 2021, 08:02:40) 
[GCC 11.1.0]
[INFO   ] Python: Interpreter at "/data/user/0/ru.iiec.pydroid3/files/arm-linux-androideabi/bin/python3"
[INFO   ] Factory: 186 symbols loaded
[INFO   ] KivyMD: 0.104.2, git-bc7d1f5, 2021-06-06 (installed at "/data/user/0/ru.iiec.pydroid3/files/arm-linux-androideabi/lib/python3.9/site-packages/kivymd/__init__.py")
[INFO   ] Image: Providers: img_tex, img_dds, img_sdl2, img_pil (img_ffpyplayer ignored)
[INFO   ] Text: Provider: sdl2
[INFO   ] Window: Provider: sdl2
[INFO   ] GL: Using the "OpenGL ES 2" graphics system
[INFO   ] GL: Backend used <sdl2>
[INFO   ] GL: OpenGL version <b'OpenGL ES 3.2 V@0502.0 (GIT@5eaa426211, I07ee46fc66, 1633700387) (Date:10/08/21)'>
[INFO   ] GL: OpenGL vendor <b'Qualcomm'>
[INFO   ] GL: OpenGL renderer <b'Adreno (TM) 610'>
[INFO   ] GL: OpenGL parsed version: 3, 2
[INFO   ] GL: Texture max size <16384>
[INFO   ] GL: Texture max units <16>
[INFO   ] Window: auto add sdl2 input provider
[INFO   ] Window: virtual keyboard not allowed, single mode, not docked
[INFO   ] Audio: Providers: audio_sdl2 (audio_android, audio_ffpyplayer ignored)
[INFO   ] Clipboard: Provider: android
[INFO   ] Loader: using a thread pool of 2 workers
[INFO   ] GL: NPOT texture support is available
[WARNING] GL: Unpack subimage support is not available
[WARNING] Base: Unknown <android> provider
[INFO   ] Base: Start application main loop
[ERROR  ] Loader: Failed to load image <https://i.ibb.co/5rpDx3v/payun.png>
Traceback (most recent call last):
  File "/data/user/0/ru.iiec.pydroid3/files/arm-linux-androideabi/lib/python3.9/urllib/request.py", line 1346, in do_open
    h.request(req.get_method(), req.selector, req.data, headers,
  File "/data/user/0/ru.iiec.pydroid3/files/arm-linux-androideabi/lib/python3.9/http/client.py", line 1279, in request
    self._send_request(method, url, body, headers, encode_chunked)
  File "/data/user/0/ru.iiec.pydroid3/files/arm-linux-androideabi/lib/python3.9/http/client.py", line 1325, in _send_request
    self.endheaders(body, encode_chunked=encode_chunked)
  File "/data/user/0/ru.iiec.pydroid3/files/arm-linux-androideabi/lib/python3.9/http/client.py", line 1274, in endheaders
    self._send_output(message_body, encode_chunked=encode_chunked)
  File "/data/user/0/ru.iiec.pydroid3/files/arm-linux-androideabi/lib/python3.9/http/client.py", line 1034, in _send_output
    self.send(msg)
  File "/data/user/0/ru.iiec.pydroid3/files/arm-linux-androideabi/lib/python3.9/http/client.py", line 974, in send
    self.connect()
  File "/data/user/0/ru.iiec.pydroid3/files/arm-linux-androideabi/lib/python3.9/http/client.py", line 1441, in connect
    super().connect()
  File "/data/user/0/ru.iiec.pydroid3/files/arm-linux-androideabi/lib/python3.9/http/client.py", line 945, in connect
    self.sock = self._create_connection(
  File "/data/user/0/ru.iiec.pydroid3/files/arm-linux-androideabi/lib/python3.9/socket.py", line 823, in create_connection
    for res in getaddrinfo(host, port, 0, SOCK_STREAM):
  File "/data/user/0/ru.iiec.pydroid3/files/arm-linux-androideabi/lib/python3.9/socket.py", line 954, in getaddrinfo
    for res in _socket.getaddrinfo(host, port, family, type, proto, flags):
socket.gaierror: [Errno 7] No address associated with hostname

During handling of the above exception, another exception occurred:

Traceback (most recent call last):
  File "/data/user/0/ru.iiec.pydroid3/files/arm-linux-androideabi/lib/python3.9/site-packages/kivy/loader.py", line 345, in _load_urllib
    fd = opener.open(request)
  File "/data/user/0/ru.iiec.pydroid3/files/arm-linux-androideabi/lib/python3.9/urllib/request.py", line 517, in open
    response = self._open(req, data)
  File "/data/user/0/ru.iiec.pydroid3/files/arm-linux-androideabi/lib/python3.9/urllib/request.py", line 534, in _open
    result = self._call_chain(self.handle_open, protocol, protocol +
  File "/data/user/0/ru.iiec.pydroid3/files/arm-linux-androideabi/lib/python3.9/urllib/request.py", line 494, in _call_chain
    result = func(*args)
  File "/data/user/0/ru.iiec.pydroid3/files/arm-linux-androideabi/lib/python3.9/urllib/request.py", line 1389, in https_open
    return self.do_open(http.client.HTTPSConnection, req,
  File "/data/user/0/ru.iiec.pydroid3/files/arm-linux-androideabi/lib/python3.9/urllib/request.py", line 1349, in do_open
    raise URLError(err)
urllib.error.URLError: <urlopen error [Errno 7] No address associated with hostname>
[INFO   ] Base: Leaving application in progress...
[WARNING] stderr: Traceback (most recent call last):
[WARNING] stderr:   File "/storage/emulated/0/matex/main.py", line 2238, in <module>
[WARNING] stderr:     TTE().run()
[WARNING] stderr:   File "/data/user/0/ru.iiec.pydroid3/files/arm-linux-androideabi/lib/python3.9/site-packages/kivy/app.py", line 950, in run
[WARNING] stderr:     runTouchApp()
[WARNING] stderr:   File "/data/user/0/ru.iiec.pydroid3/files/arm-linux-androideabi/lib/python3.9/site-packages/kivy/base.py", line 582, in runTouchApp
[WARNING] stderr:     EventLoop.mainloop()
[WARNING] stderr:   File "/data/user/0/ru.iiec.pydroid3/files/arm-linux-androideabi/lib/python3.9/site-packages/kivy/base.py", line 347, in mainloop
[WARNING] stderr:     self.idle()
[WARNING] stderr:   File "/data/user/0/ru.iiec.pydroid3/files/arm-linux-androideabi/lib/python3.9/site-packages/kivy/base.py", line 391, in idle
[WARNING] stderr:     self.dispatch_input()
[WARNING] stderr:   File "/data/user/0/ru.iiec.pydroid3/files/arm-linux-androideabi/lib/python3.9/site-packages/kivy/base.py", line 342, in dispatch_input
[WARNING] stderr:     post_dispatch_input(*pop(0))
[WARNING] stderr:   File "/data/user/0/ru.iiec.pydroid3/files/arm-linux-androideabi/lib/python3.9/site-packages/kivy/base.py", line 308, in post_dispatch_input
[WARNING] stderr:     wid.dispatch('on_touch_up', me)
[WARNING] stderr:   File "kivy/_event.pyx", line 709, in kivy._event.EventDispatcher.dispatch
[WARNING] stderr:   File "/data/user/0/ru.iiec.pydroid3/files/arm-linux-androideabi/lib/python3.9/site-packages/kivy/uix/scrollview.py", line 950, in on_touch_up
[WARNING] stderr:     if self.dispatch('on_scroll_stop', touch):
[WARNING] stderr:   File "kivy/_event.pyx", line 709, in kivy._event.EventDispatcher.dispatch
[WARNING] stderr:   File "/data/user/0/ru.iiec.pydroid3/files/arm-linux-androideabi/lib/python3.9/site-packages/kivy/uix/scrollview.py", line 989, in on_scroll_stop
[WARNING] stderr:     self.simulate_touch_down(touch)
[WARNING] stderr:   File "/data/user/0/ru.iiec.pydroid3/files/arm-linux-androideabi/lib/python3.9/site-packages/kivy/uix/scrollview.py", line 668, in simulate_touch_down
[WARNING] stderr:     ret = super(ScrollView, self).on_touch_down(touch)
[WARNING] stderr:   File "/data/user/0/ru.iiec.pydroid3/files/arm-linux-androideabi/lib/python3.9/site-packages/kivy/uix/widget.py", line 545, in on_touch_down
[WARNING] stderr:     if child.dispatch('on_touch_down', touch):
[WARNING] stderr:   File "kivy/_event.pyx", line 709, in kivy._event.EventDispatcher.dispatch
[WARNING] stderr:   File "/data/user/0/ru.iiec.pydroid3/files/arm-linux-androideabi/lib/python3.9/site-packages/kivy/uix/widget.py", line 545, in on_touch_down
[WARNING] stderr:     if child.dispatch('on_touch_down', touch):
[WARNING] stderr:   File "kivy/_event.pyx", line 709, in kivy._event.EventDispatcher.dispatch
[WARNING] stderr:   File "/data/user/0/ru.iiec.pydroid3/files/arm-linux-androideabi/lib/python3.9/site-packages/kivymd/uix/list.py", line 844, in on_touch_down
[WARNING] stderr:     super().on_touch_down(touch)
[WARNING] stderr:   File "/data/user/0/ru.iiec.pydroid3/files/arm-linux-androideabi/lib/python3.9/site-packages/kivymd/uix/behaviors/ripple_behavior.py", line 255, in on_touch_down
[WARNING] stderr:     super().on_touch_down(touch)
[WARNING] stderr:   File "/data/user/0/ru.iiec.pydroid3/files/arm-linux-androideabi/lib/python3.9/site-packages/kivy/uix/behaviors/button.py", line 151, in on_touch_down
[WARNING] stderr:     self.dispatch('on_press')
[WARNING] stderr:   File "kivy/_event.pyx", line 705, in kivy._event.EventDispatcher.dispatch
[WARNING] stderr:   File "kivy/_event.pyx", line 1248, in kivy._event.EventObservers.dispatch
[WARNING] stderr:   File "kivy/_event.pyx", line 1132, in kivy._event.EventObservers._dispatch
[WARNING] stderr:   File "/data/user/0/ru.iiec.pydroid3/files/arm-linux-androideabi/lib/python3.9/site-packages/kivy/lang/builder.py", line 57, in custom_callback
[WARNING] stderr:     exec(__kvlang__.co_value, idmap)
[WARNING] stderr:   File "<string>", line 134, in <module>
[WARNING] stderr:   File "/storage/emulated/0/matex/main.py", line 857, in donatepopup
[WARNING] stderr:     ch.execute("SELECT * FROM counter")
[WARNING] stderr: sqlite3.OperationalError: no such table: counter
